Workbook

Sheet BaseDeCalcul
D1: Niveau | E1: P01 | F1: P02 | G1: P03 | H1: C | I1: NC | J1: NA | K1: NT | P1: P01 | Q1: P02 | R1: P03 | S1: TOTAL D
A3: 1 | B3: =#REF! -> #REF! | C3: =#REF! -> #REF! | D3: A | E3: =#REF! -> #REF! | F3: =#REF! -> #REF! | G3: =#REF! -> #REF! | H3: =COUNTIF(E3:G3,"C") -> 0 | I3: =COUNTIF(E3:G3,"NC") -> 0 | J3: =COUNTIF(E3:G3,"NA") -> 0 | K3: =COUNTIF(E3:G3,"NT") -> 0 | L3: =IF(I3>0,"NC",IF(H3>0,"C",IF(K3>0,"NT","NA"))) -> NA | M3: 1 | N3: =#REF! -> #REF! | O3: =#REF! -> #REF! | P3: =#REF! -> #REF! | Q3: =#REF! -> #REF! | R3: =#REF! -> #REF! | S3: =COUNTIF(P3:R3,"D") -> 0
A4: 1 | B4: =#REF! -> #REF! | C4: =#REF! -> #REF! | D4: A | E4: =#REF! -> #REF! | F4: =#REF! -> #REF! | G4: =#REF! -> #REF! | H4: =COUNTIF(E4:G4,"C") -> 0 | I4: =COUNTIF(E4:G4,"NC") -> 0 | J4: =COUNTIF(E4:G4,"NA") -> 0 | K4: =COUNTIF(E4:G4,"NT") -> 0 | L4: =IF(I4>0,"NC",IF(H4>0,"C",IF(K4>0,"NT","NA"))) -> NA | M4: 1 | N4: =#REF! -> #REF! | O4: =#REF! -> #REF! | P4: =#REF! -> #REF! | Q4: =#REF! -> #REF! | R4: =#REF! -> #REF! | S4: =COUNTIF(P4:R4,"D") -> 0
A5: 1 | B5: =#REF! -> #REF! | C5: =#REF! -> #REF! | D5: A | E5: =#REF! -> #REF! | F5: =#REF! -> #REF! | G5: =#REF! -> #REF! | H5: =COUNTIF(E5:G5,"C") -> 0 | I5: =COUNTIF(E5:G5,"NC") -> 0 | J5: =COUNTIF(E5:G5,"NA") -> 0 | K5: =COUNTIF(E5:G5,"NT") -> 0 | L5: =IF(I5>0,"NC",IF(H5>0,"C",IF(K5>0,"NT","NA"))) -> NA | M5: 1 | N5: =#REF! -> #REF! | O5: =#REF! -> #REF! | P5: =#REF! -> #REF! | Q5: =#REF! -> #REF! | R5: =#REF! -> #REF! | S5: =COUNTIF(P5:R5,"D") -> 0
A6: 1 | B6: =#REF! -> #REF! | C6: =#REF! -> #REF! | D6: A | E6: =#REF! -> #REF! | F6: =#REF! -> #REF! | G6: =#REF! -> #REF! | H6: =COUNTIF(E6:G6,"C") -> 0 | I6: =COUNTIF(E6:G6,"NC") -> 0 | J6: =COUNTIF(E6:G6,"NA") -> 0 | K6: =COUNTIF(E6:G6,"NT") -> 0 | L6: =IF(I6>0,"NC",IF(H6>0,"C",IF(K6>0,"NT","NA"))) -> NA | M6: 1 | N6: =#REF! -> #REF! | O6: =#REF! -> #REF! | P6: =#REF! -> #REF! | Q6: =#REF! -> #REF! | R6: =#REF! -> #REF! | S6: =COUNTIF(P6:R6,"D") -> 0
A7: 1 | B7: =#REF! -> #REF! | C7: =#REF! -> #REF! | D7: A | E7: =#REF! -> #REF! | F7: =#REF! -> #REF! | G7: =#REF! -> #REF! | H7: =COUNTIF(E7:G7,"C") -> 0 | I7: =COUNTIF(E7:G7,"NC") -> 0 | J7: =COUNTIF(E7:G7,"NA") -> 0 | K7: =COUNTIF(E7:G7,"NT") -> 0 | L7: =IF(I7>0,"NC",IF(H7>0,"C",IF(K7>0,"NT","NA"))) -> NA | M7: 1 | N7: =#REF! -> #REF! | O7: =#REF! -> #REF! | P7: =#REF! -> #REF! | Q7: =#REF! -> #REF! | R7: =#REF! -> #REF! | S7: =COUNTIF(P7:R7,"D") -> 0
A8: 1 | B8: =#REF! -> #REF! | C8: =#REF! -> #REF! | D8: A | E8: =#REF! -> #REF! | F8: =#REF! -> #REF! | G8: =#REF! -> #REF! | H8: =COUNTIF(E8:G8,"C") -> 0 | I8: =COUNTIF(E8:G8,"NC") -> 0 | J8: =COUNTIF(E8:G8,"NA") -> 0 | K8: =COUNTIF(E8:G8,"NT") -> 0 | L8: =IF(I8>0,"NC",IF(H8>0,"C",IF(K8>0,"NT","NA"))) -> NA | M8: 1 | N8: =#REF! -> #REF! | O8: =#REF! -> #REF! | P8: =#REF! -> #REF! | Q8: =#REF! -> #REF! | R8: =#REF! -> #REF! | S8: =COUNTIF(P8:R8,"D") -> 0
A9: 1 | B9: =#REF! -> #REF! | C9: =#REF! -> #REF! | D9: A | E9: =#REF! -> #REF! | F9: =#REF! -> #REF! | G9: =#REF! -> #REF! | H9: =COUNTIF(E9:G9,"C") -> 0 | I9: =COUNTIF(E9:G9,"NC") -> 0 | J9: =COUNTIF(E9:G9,"NA") -> 0 | K9: =COUNTIF(E9:G9,"NT") -> 0 | L9: =IF(I9>0,"NC",IF(H9>0,"C",IF(K9>0,"NT","NA"))) -> NA | M9: 1 | N9: =#REF! -> #REF! | O9: =#REF! -> #REF! | P9: =#REF! -> #REF! | Q9: =#REF! -> #REF! | R9: =#REF! -> #REF! | S9: =COUNTIF(P9:R9,"D") -> 0
H10: =SUM(H3:H9) -> 0 | I10: =SUM(I3:I9) -> 0 | J10: =SUM(J3:J9) -> 0 | K10: =SUM(K3:K9) -> 0 | S10: =SUM(S1:S9) -> 0
A11: 2 | B11: =#REF! -> #REF! | C11: =#REF! -> #REF! | D11: A | E11: =#REF! -> #REF! | F11: =#REF! -> #REF! | G11: =#REF! -> #REF! | H11: =COUNTIF(E11:G11,"C") -> 0 | I11: =COUNTIF(E11:G11,"NC") -> 0 | J11: =COUNTIF(E11:G11,"NA") -> 0 | K11: =COUNTIF(E11:G11,"NT") -> 0 | L11: =IF(I11>0,"NC",IF(H11>0,"C",IF(K11>0,"NT","NA"))) -> NA | M11: 2 | N11: =#REF! -> #REF! | O11: =#REF! -> #REF! | P11: =#REF! -> #REF! | Q11: =#REF! -> #REF! | R11: =#REF! -> #REF! | S11: =COUNTIF(P11:R11,"D") -> 0
H12: =SUM(H11:H11) -> 0 | I12: =SUM(I11:I11) -> 0 | J12: =SUM(J11:J11) -> 0 | K12: =SUM(K11:K11) -> 0 | S12: =SUM(S11:S11) -> 0
A13: 3 | B13: =#REF! -> #REF! | C13: =#REF! -> #REF! | D13: A | E13: =#REF! -> #REF! | F13: =#REF! -> #REF! | G13: =#REF! -> #REF! | H13: =COUNTIF(E13:G13,"C") -> 0 | I13: =COUNTIF(E13:G13,"NC") -> 0 | J13: =COUNTIF(E13:G13,"NA") -> 0 | K13: =COUNTIF(E13:G13,"NT") -> 0 | L13: =IF(I13>0,"NC",IF(H13>0,"C",IF(K13>0,"NT","NA"))) -> NA | M13: 3 | N13: =#REF! -> #REF! | O13: =#REF! -> #REF! | P13: =#REF! -> #REF! | Q13: =#REF! -> #REF! | R13: =#REF! -> #REF! | S13: =COUNTIF(P13:R13,"D") -> 0
A14: 3 | B14: =#REF! -> #REF! | C14: =#REF! -> #REF! | D14: AA | E14: =#REF! -> #REF! | F14: =#REF! -> #REF! | G14: =#REF! -> #REF! | H14: =COUNTIF(E14:G14,"C") -> 0 | I14: =COUNTIF(E14:G14,"NC") -> 0 | J14: =COUNTIF(E14:G14,"NA") -> 0 | K14: =COUNTIF(E14:G14,"NT") -> 0 | L14: =IF(I14>0,"NC",IF(H14>0,"C",IF(K14>0,"NT","NA"))) -> NA | M14: 3 | N14: =#REF! -> #REF! | O14: =#REF! -> #REF! | P14: =#REF! -> #REF! | Q14: =#REF! -> #REF! | R14: =#REF! -> #REF! | S14: =COUNTIF(P14:R14,"D") -> 0
H15: =SUM(H13:H14) -> 0 | I15: =SUM(I13:I14) -> 0 | J15: =SUM(J13:J14) -> 0 | K15: =SUM(K13:K14) -> 0 | S15: =SUM(S13:S14) -> 0
A16: 4 | B16: =#REF! -> #REF! | C16: =#REF! -> #REF! | D16: A | E16: =#REF! -> #REF! | F16: =#REF! -> #REF! | G16: =#REF! -> #REF! | H16: =COUNTIF(E16:G16,"C") -> 0 | I16: =COUNTIF(E16:G16,"NC") -> 0 | J16: =COUNTIF(E16:G16,"NA") -> 0 | K16: =COUNTIF(E16:G16,"NT") -> 0 | L16: =IF(I16>0,"NC",IF(H16>0,"C",IF(K16>0,"NT","NA"))) -> NA | M16: 4 | N16: =#REF! -> #REF! | O16: =#REF! -> #REF! | P16: =#REF! -> #REF! | Q16: =#REF! -> #REF! | R16: =#REF! -> #REF! | S16: =COUNTIF(P16:R16,"D") -> 0
A17: 4 | B17: =#REF! -> #REF! | C17: =#REF! -> #REF! | D17: A | E17: =#REF! -> #REF! | F17: =#REF! -> #REF! | G17: =#REF! -> #REF! | H17: =COUNTIF(E17:G17,"C") -> 0 | I17: =COUNTIF(E17:G17,"NC") -> 0 | J17: =COUNTIF(E17:G17,"NA") -> 0 | K17: =COUNTIF(E17:G17,"NT") -> 0 | L17: =IF(I17>0,"NC",IF(H17>0,"C",IF(K17>0,"NT","NA"))) -> NA | M17: 4 | N17: =#REF! -> #REF! | O17: =#REF! -> #REF! | P17: =#REF! -> #REF! | Q17: =#REF! -> #REF! | R17: =#REF! -> #REF! | S17: =COUNTIF(P17:R17,"D") -> 0
A18: 4 | B18: =#REF! -> #REF! | C18: =#REF! -> #REF! | D18: A | E18: =#REF! -> #REF! | F18: =#REF! -> #REF! | G18: =#REF! -> #REF! | H18: =COUNTIF(E18:G18,"C") -> 0 | I18: =COUNTIF(E18:G18,"NC") -> 0 | J18: =COUNTIF(E18:G18,"NA") -> 0 | K18: =COUNTIF(E18:G18,"NT") -> 0 | L18: =IF(I18>0,"NC",IF(H18>0,"C",IF(K18>0,"NT","NA"))) -> NA | M18: 4 | N18: =#REF! -> #REF! | O18: =#REF! -> #REF! | P18: =#REF! -> #REF! | Q18: =#REF! -> #REF! | R18: =#REF! -> #REF! | S18: =COUNTIF(P18:R18,"D") -> 0
A19: 4 | B19: =#REF! -> #REF! | C19: =#REF! -> #REF! | D19: A | E19: =#REF! -> #REF! | F19: =#REF! -> #REF! | G19: =#REF! -> #REF! | H19: =COUNTIF(E19:G19,"C") -> 0 | I19: =COUNTIF(E19:G19,"NC") -> 0 | J19: =COUNTIF(E19:G19,"NA") -> 0 | K19: =COUNTIF(E19:G19,"NT") -> 0 | L19: =IF(I19>0,"NC",IF(H19>0,"C",IF(K19>0,"NT","NA"))) -> NA | M19: 4 | N19: =#REF! -> #REF! | O19: =#REF! -> #REF! | P19: =#REF! -> #REF! | Q19: =#REF! -> #REF! | R19: =#REF! -> #REF! | S19: =COUNTIF(P19:R19,"D") -> 0
A20: 4 | B20: =#REF! -> #REF! | C20: =#REF! -> #REF! | D20: A | E20: =#REF! -> #REF! | F20: =#REF! -> #REF! | G20: =#REF! -> #REF! | H20: =COUNTIF(E20:G20,"C") -> 0 | I20: =COUNTIF(E20:G20,"NC") -> 0 | J20: =COUNTIF(E20:G20,"NA") -> 0 | K20: =COUNTIF(E20:G20,"NT") -> 0 | L20: =IF(I20>0,"NC",IF(H20>0,"C",IF(K20>0,"NT","NA"))) -> NA | M20: 4 | N20: =#REF! -> #REF! | O20: =#REF! -> #REF! | P20: =#REF! -> #REF! | Q20: =#REF! -> #REF! | R20: =#REF! -> #REF! | S20: =COUNTIF(P20:R20,"D") -> 0
A21: 4 | B21: =#REF! -> #REF! | C21: =#REF! -> #REF! | D21: A | E21: =#REF! -> #REF! | F21: =#REF! -> #REF! | G21: =#REF! -> #REF! | H21: =COUNTIF(E21:G21,"C") -> 0 | I21: =COUNTIF(E21:G21,"NC") -> 0 | J21: =COUNTIF(E21:G21,"NA") -> 0 | K21: =COUNTIF(E21:G21,"NT") -> 0 | L21: =IF(I21>0,"NC",IF(H21>0,"C",IF(K21>0,"NT","NA"))) -> NA | M21: 4 | N21: =#REF! -> #REF! | O21: =#REF! -> #REF! | P21: =#REF! -> #REF! | Q21: =#REF! -> #REF! | R21: =#REF! -> #REF! | S21: =COUNTIF(P21:R21,"D") -> 0
A22: 4 | B22: =#REF! -> #REF! | C22: =#REF! -> #REF! | D22: A | E22: =#REF! -> #REF! | F22: =#REF! -> #REF! | G22: =#REF! -> #REF! | H22: =COUNTIF(E22:G22,"C") -> 0 | I22: =COUNTIF(E22:G22,"NC") -> 0 | J22: =COUNTIF(E22:G22,"NA") -> 0 | K22: =COUNTIF(E22:G22,"NT") -> 0 | L22: =IF(I22>0,"NC",IF(H22>0,"C",IF(K22>0,"NT","NA"))) -> NA | M22: 4 | N22: =#REF! -> #REF! | O22: =#REF! -> #REF! | P22: =#REF! -> #REF! | Q22: =#REF! -> #REF! | R22: =#REF! -> #REF! | S22: =COUNTIF(P22:R22,"D") -> 0
A23: 4 | B23: =#REF! -> #REF! | C23: =#REF! -> #REF! | D23: A | E23: =#REF! -> #REF! | F23: =#REF! -> #REF! | G23: =#REF! -> #REF! | H23: =COUNTIF(E23:G23,"C") -> 0 | I23: =COUNTIF(E23:G23,"NC") -> 0 | J23: =COUNTIF(E23:G23,"NA") -> 0 | K23: =COUNTIF(E23:G23,"NT") -> 0 | L23: =IF(I23>0,"NC",IF(H23>0,"C",IF(K23>0,"NT","NA"))) -> NA | M23: 4 | N23: =#REF! -> #REF! | O23: =#REF! -> #REF! | P23: =#REF! -> #REF! | Q23: =#REF! -> #REF! | R23: =#REF! -> #REF! | S23: =COUNTIF(P23:R23,"D") -> 0
H24: =SUM(H16:H23) -> 0 | I24: =SUM(I16:I23) -> 0 | J24: =SUM(J16:J23) -> 0 | K24: =SUM(K16:K23) -> 0 | S24: =SUM(S16:S23) -> 0
A25: 5 | B25: =#REF! -> #REF! | C25: =#REF! -> #REF! | D25: A | E25: =#REF! -> #REF! | F25: =#REF! -> #REF! | G25: =#REF! -> #REF! | H25: =COUNTIF(E25:G25,"C") -> 0 | I25: =COUNTIF(E25:G25,"NC") -> 0 | J25: =COUNTIF(E25:G25,"NA") -> 0 | K25: =COUNTIF(E25:G25,"NT") -> 0 | L25: =IF(I25>0,"NC",IF(H25>0,"C",IF(K25>0,"NT","NA"))) -> NA | M25: 5 | N25: =#REF! -> #REF! | O25: =#REF! -> #REF! | P25: =#REF! -> #REF! | Q25: =#REF! -> #REF! | R25: =#REF! -> #REF! | S25: =COUNTIF(P25:R25,"D") -> 0
A26: 5 | B26: =#REF! -> #REF! | C26: =#REF! -> #REF! | D26: A | E26: =#REF! -> #REF! | F26: =#REF! -> #REF! | G26: =#REF! -> #REF! | H26: =COUNTIF(E26:G26,"C") -> 0 | I26: =COUNTIF(E26:G26,"NC") -> 0 | J26: =COUNTIF(E26:G26,"NA") -> 0 | K26: =COUNTIF(E26:G26,"NT") -> 0 | L26: =IF(I26>0,"NC",IF(H26>0,"C",IF(K26>0,"NT","NA"))) -> NA | M26: 5 | N26: =#REF! -> #REF! | O26: =#REF! -> #REF! | P26: =#REF! -> #REF! | Q26: =#REF! -> #REF! | R26: =#REF! -> #REF! | S26: =COUNTIF(P26:R26,"D") -> 0
H27: =SUM(H25:H26) -> 0 | I27: =SUM(I25:I26) -> 0 | J27: =SUM(J25:J26) -> 0 | K27: =SUM(K25:K26) -> 0 | S27: =SUM(S25:S26) -> 0
A28: 6 | B28: =#REF! -> #REF! | C28: =#REF! -> #REF! | D28: A | E28: =#REF! -> #REF! | F28: =#REF! -> #REF! | G28: =#REF! -> #REF! | H28: =COUNTIF(E28:G28,"C") -> 0 | I28: =COUNTIF(E28:G28,"NC") -> 0 | J28: =COUNTIF(E28:G28,"NA") -> 0 | K28: =COUNTIF(E28:G28,"NT") -> 0 | L28: =IF(I28>0,"NC",IF(H28>0,"C",IF(K28>0,"NT","NA"))) -> NA | M28: 6 | N28: =#REF! -> #REF! | O28: =#REF! -> #REF! | P28: =#REF! -> #REF! | Q28: =#REF! -> #REF! | R28: =#REF! -> #REF! | S28: =COUNTIF(P28:R28,"D") -> 0
A29: 6 | B29: =#REF! -> #REF! | C29: =#REF! -> #REF! | D29: A | E29: =#REF! -> #REF! | F29: =#REF! -> #REF! | G29: =#REF! -> #REF! | H29: =COUNTIF(E29:G29,"C") -> 0 | I29: =COUNTIF(E29:G29,"NC") -> 0 | J29: =COUNTIF(E29:G29,"NA") -> 0 | K29: =COUNTIF(E29:G29,"NT") -> 0 | L29: =IF(I29>0,"NC",IF(H29>0,"C",IF(K29>0,"NT","NA"))) -> NA | M29: 6 | N29: =#REF! -> #REF! | O29: =#REF! -> #REF! | P29: =#REF! -> #REF! | Q29: =#REF! -> #REF! | R29: =#REF! -> #REF! | S29: =COUNTIF(P29:R29,"D") -> 0
H30: =SUM(H28:H29) -> 0 | I30: =SUM(I28:I29) -> 0 | J30: =SUM(J28:J29) -> 0 | K30: =SUM(K28:K29) -> 0 | S30: =SUM(S28:S29) -> 0
A31: 7 | B31: =#REF! -> #REF! | C31: =#REF! -> #REF! | D31: A | E31: =#REF! -> #REF! | F31: =#REF! -> #REF! | G31: =#REF! -> #REF! | H31: =COUNTIF(E31:G31,"C") -> 0 | I31: =COUNTIF(E31:G31,"NC") -> 0 | J31: =COUNTIF(E31:G31,"NA") -> 0 | K31: =COUNTIF(E31:G31,"NT") -> 0 | L31: =IF(I31>0,"NC",IF(H31>0,"C",IF(K31>0,"NT","NA"))) -> NA | M31: 7 | N31: =#REF! -> #REF! | O31: =#REF! -> #REF! | P31: =#REF! -> #REF! | Q31: =#REF! -> #REF! | R31: =#REF! -> #REF! | S31: =COUNTIF(P31:R31,"D") -> 0
H32: =SUM(H31:H31) -> 0 | I32: =SUM(I31:I31) -> 0 | J32: =SUM(J31:J31) -> 0 | K32: =SUM(K31:K31) -> 0 | S32: =SUM(S31:S31) -> 0
A33: 8 | B33: 8.1 | C33: =#REF! -> #REF! | D33: A | E33: =#REF! -> #REF! | F33: =#REF! -> #REF! | G33: =#REF! -> #REF! | H33: =COUNTIF(E33:G33,"C") -> 0 | I33: =COUNTIF(E33:G33,"NC") -> 0 | J33: =COUNTIF(E33:G33,"NA") -> 0 | K33: =COUNTIF(E33:G33,"NT") -> 0 | L33: =IF(I33>0,"NC",IF(H33>0,"C",IF(K33>0,"NT","NA"))) -> NA | M33: 8 | N33: 8.1 | O33: =#REF! -> #REF! | P33: =#REF! -> #REF! | Q33: =#REF! -> #REF! | R33: =#REF! -> #REF! | S33: =COUNTIF(P33:R33,"D") -> 0
A34: 8 | B34: 8.2 | C34: =#REF! -> #REF! | D34: A | E34: =#REF! -> #REF! | F34: =#REF! -> #REF! | G34: =#REF! -> #REF! | H34: =COUNTIF(E34:G34,"C") -> 0 | I34: =COUNTIF(E34:G34,"NC") -> 0 | J34: =COUNTIF(E34:G34,"NA") -> 0 | K34: =COUNTIF(E34:G34,"NT") -> 0 | L34: =IF(I34>0,"NC",IF(H34>0,"C",IF(K34>0,"NT","NA"))) -> NA | M34: 8 | N34: 8.2 | O34: =#REF! -> #REF! | P34: =#REF! -> #REF! | Q34: =#REF! -> #REF! | R34: =#REF! -> #REF! | S34: =COUNTIF(P34:R34,"D") -> 0
A35: 8 | B35: 8.3 | C35: =#REF! -> #REF! | D35: A | E35: =#REF! -> #REF! | F35: =#REF! -> #REF! | G35: =#REF! -> #REF! | H35: =COUNTIF(E35:G35,"C") -> 0 | I35: =COUNTIF(E35:G35,"NC") -> 0 | J35: =COUNTIF(E35:G35,"NA") -> 0 | K35: =COUNTIF(E35:G35,"NT") -> 0 | L35: =IF(I35>0,"NC",IF(H35>0,"C",IF(K35>0,"NT","NA"))) -> NA | M35: 8 | N35: 8.3 | O35: =#REF! -> #REF! | P35: =#REF! -> #REF! | Q35: =#REF! -> #REF! | R35: =#REF! -> #REF! | S35: =COUNTIF(P35:R35,"D") -> 0
A36: 8 | B36: =#REF! -> #REF! | C36: =#REF! -> #REF! | D36: A | E36: =#REF! -> #REF! | F36: =#REF! -> #REF! | G36: =#REF! -> #REF! | H36: =COUNTIF(E36:G36,"C") -> 0 | I36: =COUNTIF(E36:G36,"NC") -> 0 | J36: =COUNTIF(E36:G36,"NA") -> 0 | K36: =COUNTIF(E36:G36,"NT") -> 0 | L36: =IF(I36>0,"NC",IF(H36>0,"C",IF(K36>0,"NT","NA"))) -> NA | M36: 8 | N36: =#REF! -> #REF! | O36: =#REF! -> #REF! | P36: =#REF! -> #REF! | Q36: =#REF! -> #REF! | R36: =#REF! -> #REF! | S36: =COUNTIF(P36:R36,"D") -> 0
A37: 8 | B37: =#REF! -> #REF! | C37: =#REF! -> #REF! | D37: A | E37: =#REF! -> #REF! | F37: =#REF! -> #REF! | G37: =#REF! -> #REF! | H37: =COUNTIF(E37:G37,"C") -> 0 | I37: =COUNTIF(E37:G37,"NC") -> 0 | J37: =COUNTIF(E37:G37,"NA") -> 0 | K37: =COUNTIF(E37:G37,"NT") -> 0 | L37: =IF(I37>0,"NC",IF(H37>0,"C",IF(K37>0,"NT","NA"))) -> NA | M37: 8 | N37: =#REF! -> #REF! | O37: =#REF! -> #REF! | P37: =#REF! -> #REF! | Q37: =#REF! -> #REF! | R37: =#REF! -> #REF! | S37: =COUNTIF(P37:R37,"D") -> 0
A38: 8 | B38: =#REF! -> #REF! | C38: =#REF! -> #REF! | D38: A | E38: =#REF! -> #REF! | F38: =#REF! -> #REF! | G38: =#REF! -> #REF! | H38: =COUNTIF(E38:G38,"C") -> 0 | I38: =COUNTIF(E38:G38,"NC") -> 0 | J38: =COUNTIF(E38:G38,"NA") -> 0 | K38: =COUNTIF(E38:G38,"NT") -> 0 | L38: =IF(I38>0,"NC",IF(H38>0,"C",IF(K38>0,"NT","NA"))) -> NA | M38: 8 | N38: =#REF! -> #REF! | O38: =#REF! -> #REF! | P38: =#REF! -> #REF! | Q38: =#REF! -> #REF! | R38: =#REF! -> #REF! | S38: =COUNTIF(P38:R38,"D") -> 0
A39: 8 | B39: =#REF! -> #REF! | C39: =#REF! -> #REF! | D39: AA | E39: =#REF! -> #REF! | F39: =#REF! -> #REF! | G39: =#REF! -> #REF! | H39: =COUNTIF(E39:G39,"C") -> 0 | I39: =COUNTIF(E39:G39,"NC") -> 0 | J39: =COUNTIF(E39:G39,"NA") -> 0 | K39: =COUNTIF(E39:G39,"NT") -> 0 | L39: =IF(I39>0,"NC",IF(H39>0,"C",IF(K39>0,"NT","NA"))) -> NA | M39: 8 | N39: =#REF! -> #REF! | O39: =#REF! -> #REF! | P39: =#REF! -> #REF! | Q39: =#REF! -> #REF! | R39: =#REF! -> #REF! | S39: =COUNTIF(P39:R39,"D") -> 0
A40: 8 | B40: =#REF! -> #REF! | C40: =#REF! -> #REF! | D40: AA | E40: =#REF! -> #REF! | F40: =#REF! -> #REF! | G40: =#REF! -> #REF! | H40: =COUNTIF(E40:G40,"C") -> 0 | I40: =COUNTIF(E40:G40,"NC") -> 0 | J40: =COUNTIF(E40:G40,"NA") -> 0 | K40: =COUNTIF(E40:G40,"NT") -> 0 | L40: =IF(I40>0,"NC",IF(H40>0,"C",IF(K40>0,"NT","NA"))) -> NA | M40: 8 | N40: =#REF! -> #REF! | O40: =#REF! -> #REF! | P40: =#REF! -> #REF! | Q40: =#REF! -> #REF! | R40: =#REF! -> #REF! | S40: =COUNTIF(P40:R40,"D") -> 0
H41: =SUM(H34:H40) -> 0 | I41: =SUM(I34:I40) -> 0 | J41: =SUM(J34:J40) -> 0 | K41: =SUM(K33:K40) -> 0 | S41: =SUM(S33:S40) -> 0
...

Sheet Synthèse
A1: =#REF! -> #REF!
A2: Synthèse par thématiques et par statuts
B3: Statut | C3: IMAGES | D3: CADRES | E3: COULEURS | F3: MULTIMÉDIA | G3: TABLEAUX | H3: LIENS | I3: SCRIPTS | J3: ÉLÉMENTS OBLIGATOIRES | K3: STRUCTURATION | L3: PRÉSENTATION | M3: FORMULAIRES | N3: NAVIGATION | O3: CONSULTATION
B6: C | C6: =BaseDeCalcul!$H10 -> 0 | D6: =BaseDeCalcul!H12 -> 0 | E6: =BaseDeCalcul!H15 -> 0 | F6: =BaseDeCalcul!H24 -> 0 | G6: =BaseDeCalcul!H27 -> 0 | H6: =BaseDeCalcul!H30 -> 0 | I6: =BaseDeCalcul!H32 -> 0 | J6: =BaseDeCalcul!H41 -> 0 | K6: =BaseDeCalcul!H44 -> 0 | L6: =BaseDeCalcul!H50 -> 0 | M6: =BaseDeCalcul!H58 -> 0 | N6: =BaseDeCalcul!H64 -> 0 | O6: =BaseDeCalcul!H68 -> 0 | Q6: =SUM(C6:O6) -> 0 | R6: C
B7: NC | C7: =BaseDeCalcul!I10 -> 0 | D7: =BaseDeCalcul!I12 -> 0 | E7: =BaseDeCalcul!I15 -> 0 | F7: =BaseDeCalcul!I24 -> 0 | G7: =BaseDeCalcul!I27 -> 0 | H7: =BaseDeCalcul!I30 -> 0 | I7: =BaseDeCalcul!I32 -> 0 | J7: =BaseDeCalcul!I41 -> 0 | K7: =BaseDeCalcul!I44 -> 0 | L7: =BaseDeCalcul!I50 -> 0 | M7: =BaseDeCalcul!I58 -> 0 | N7: =BaseDeCalcul!I64 -> 0 | O7: =BaseDeCalcul!I68 -> 0 | Q7: =SUM(C7:O7) -> 0 | R7: NC
B8: NA | C8: =BaseDeCalcul!J10 -> 0 | D8: =BaseDeCalcul!J12 -> 0 | E8: =BaseDeCalcul!J15 -> 0 | F8: =BaseDeCalcul!J24 -> 0 | G8: =BaseDeCalcul!J27 -> 0 | H8: =BaseDeCalcul!J30 -> 0 | I8: =BaseDeCalcul!J32 -> 0 | J8: =BaseDeCalcul!J41 -> 0 | K8: =BaseDeCalcul!J44 -> 0 | L8: =BaseDeCalcul!J50 -> 0 | M8: =BaseDeCalcul!J58 -> 0 | N8: =BaseDeCalcul!J64 -> 0 | O8: =BaseDeCalcul!J68 -> 0 | Q8: =SUM(C8:O8) -> 0 | R8: NA
B9: D | C9: =BaseDeCalcul!S10 -> 0 | D9: =BaseDeCalcul!S12 -> 0 | E9: =BaseDeCalcul!S15 -> 0 | F9: =BaseDeCalcul!S24 -> 0 | G9: =BaseDeCalcul!S27 -> 0 | H9: =BaseDeCalcul!S30 -> 0 | I9: =BaseDeCalcul!S32 -> 0 | J9: =BaseDeCalcul!S41 -> 0 | K9: =BaseDeCalcul!S44 -> 0 | L9: =BaseDeCalcul!S50 -> 0 | M9: =BaseDeCalcul!S58 -> 0 | N9: =BaseDeCalcul!S64 -> 0 | O9: =BaseDeCalcul!S68 -> 0 | Q9: =SUM(C9:O9) -> 0 | R9: D
B10: NT | C10: =BaseDeCalcul!K10 -> 0 | D10: =BaseDeCalcul!K12 -> 0 | E10: =BaseDeCalcul!K15 -> 0 | F10: =BaseDeCalcul!K24 -> 0 | G10: =BaseDeCalcul!K27 -> 0 | H10: =BaseDeCalcul!K30 -> 0 | I10: =BaseDeCalcul!K32 -> 0 | J10: =BaseDeCalcul!K41 -> 0 | K10: =BaseDeCalcul!K44 -> 0 | L10: =BaseDeCalcul!K50 -> 0 | M10: =BaseDeCalcul!K58 -> 0 | N10: =BaseDeCalcul!K64 -> 0 | O10: =BaseDeCalcul!K68 -> 0 | Q10: =SUM(C10:O10) -> 0 | R10: NT
B14: Pourcentage de critères respectés (somme des critères conformes divisée par le nombre de critères applicables) :
B15: =IF(Q10=0,ROUND(COUNTIF(BaseDeCalcul!L3:L67,"C")/(COUNTIF(BaseDeCalcul!L3:L67,"C")+COUNTIF(BaseDeCalcul!L3:L67,"NC"))*100, 2)&"%","Pourcentage indisponible : il reste "&Q10&" critère(s) NT.") -> #DIV/0!
B17: Taux moyen de conformité du service en ligne (moyenne des taux de conformité de chaque page) :
B18: =IF(Q10=0,ROUND(AVERAGEIF(BaseDeCalcul!E72:G72,"<>NA")*100,1)&"%","Pourcentage indisponible : il reste "&Q10&" critère(s) NT.") -> #DIV/0!
B20: =B15*100 -> #DIV/0!
B21: =IF(AND(Synthèse!B20>=Échelle!A2, Synthèse!B20<Échelle!B2), Échelle!C2, IF(AND(Synthèse!B20>=Échelle!A3, Synthèse!B20<Échelle!B3), Échelle!C3, IF(AND(Synthèse!B20>=Échelle!A4, Synthèse!B20<Échelle!B4), Échelle!C4, IF(AND(Synthèse!B20>=Échelle!A5, Synthèse!B20<Échelle!B5), Échelle!C5, IF(AND(Synthèse!B20>=Échelle!A6, Synthèse!B20<=Échelle!B6), Échelle!C6, "" ) ) ) ) ) -> #DIV/0!
C36: 1
C43: 1
C57: 1
C58: 1
C67: 1
C68: 1
C69: 1
C70: 1
C71: 1
C87: 1
C88: 1
C89: 1
... C119: 1

Sheet Échelle
A1: start % | B1: end % | C1: Label
A2: 0 | B2: 20 | C2: très faible
A3: 20 | B3: 40 | C3: faible
A4: 40 | B4: 60 | C4: moyen
A5: 60 | B5: 80 | C5: bon
A6: 80 | B6: 100 | C6: très bon

Sheet Échantillon
A1: AUDIT SIMPLIFIÉ – GRILLE D'ÉVALUATION
A2: Échantillon évalué
A3: Date :
A4: Site :
A6: N° page | B6: Titre de la page | C6: URL
A7: P01
A8: P02
A9: P03

Sheet P01
A1: Critère-INC | B1: Critère | C1: Recommandation | D1: Auto-NA | E1: Statut | F1: Dérogation | G1: Problèmes détectés | H1: Check-Problèmes-Détectés | I1: ="P01 " & COUNTA(E2:E54) &"/"&COUNTA(C2:C54) -> P01 0/53 | J1: P02 | K1: P03
A2: 1 | B2: 1.1 | C2: Chaque image porteuse d’information a-t-elle une alternative textuelle ? | H2: =IF(AND(E2="NC",G2=""),"Il manque un message d'erreur", IF(AND(E2<>"NC",G2<>""),"Il faut seulement écrire un message d'erreur pour NC","")) | I2: =E2 -> 0 | J2: ='P02'!E2 -> 0 | K2: ='P03'!K2 -> 0
A3: 2 | B3: 1.2 | C3: Chaque image de décoration est-elle correctement ignorée par les technologies d’assistance ? | H3: =IF(AND(E3="NC",G3=""),"Il manque un message d'erreur", IF(AND(E3<>"NC",G3<>""),"Il faut seulement écrire un message d'erreur pour NC","")) | I3: =E3 -> 0 | J3: ='P02'!E3 -> 0 | K3: ='P03'!K3 -> 0
A4: 3 | B4: 1.3 | C4: Pour chaque image porteuse d'information ayant une alternative textuelle, cette alternative est-elle pertinente (hors cas particuliers) ? | D4: =IF(OR(E2="NA",E2="NC"),"NA",T3) -> 0 | H4: =IF(AND(E4="NC",G4=""),"Il manque un message d'erreur", IF(AND(E4<>"NC",G4<>""),"Il faut seulement écrire un message d'erreur pour NC","")) | I4: =E4 -> 0 | J4: ='P02'!E4 -> 0 | K4: ='P03'!K4 -> 0
A5: 4 | B5: 1.4 | C5: Pour chaque image utilisée comme CAPTCHA ou comme image-test, ayant une alternative textuelle, cette alternative permet-elle d’identifier la nature et la fonction de l’image ? | H5: =IF(AND(E5="NC",G5=""),"Il manque un message d'erreur", IF(AND(E5<>"NC",G5<>""),"Il faut seulement écrire un message d'erreur pour NC","")) | I5: =E5 -> 0 | J5: ='P02'!E5 -> 0 | K5: ='P03'!K5 -> 0
A6: 5 | B6: 1.5 | C6: Pour chaque image utilisée comme CAPTCHA, une solution d’accès alternatif au contenu ou à la fonction du CAPTCHA est-elle présente ? | H6: =IF(AND(E6="NC",G6=""),"Il manque un message d'erreur", IF(AND(E6<>"NC",G6<>""),"Il faut seulement écrire un message d'erreur pour NC","")) | I6: =E6 -> 0 | J6: ='P02'!E6 -> 0 | K6: ='P03'!K6 -> 0
A7: 6 | B7: 1.6 | C7: Chaque image porteuse d’information a-t-elle, si nécessaire, une description détaillée ? | D7: =IF(OR(E2="NA",E2="NC"),"NA",T6) -> 0 | H7: =IF(AND(E7="NC",G7=""),"Il manque un message d'erreur", IF(AND(E7<>"NC",G7<>""),"Il faut seulement écrire un message d'erreur pour NC","")) | I7: =E7 -> 0 | J7: ='P02'!E7 -> 0 | K7: ='P03'!K7 -> 0
A8: 7 | B8: 1.7 | C8: Pour chaque image porteuse d’information ayant une description détaillée, cette description est-elle pertinente ? | D8: =IF(OR(E2="NA",E2="NC"),"NA",T7) -> 0 | H8: =IF(AND(E8="NC",G8=""),"Il manque un message d'erreur", IF(AND(E8<>"NC",G8<>""),"Il faut seulement écrire un message d'erreur pour NC","")) | I8: =E8 -> 0 | J8: ='P02'!E8 -> 0 | K8: ='P03'!K8 -> 0
A9: 8 | B9: 2.1 | C9: Chaque cadre a-t-il un titre de cadre ? | H9: =IF(AND(E9="NC",G9=""),"Il manque un message d'erreur", IF(AND(E9<>"NC",G9<>""),"Il faut seulement écrire un message d'erreur pour NC","")) | I9: =E9 -> 0 | J9: ='P02'!E9 -> 0 | K9: ='P03'!K9 -> 0
A10: 9 | B10: 3.1 | C10: Dans chaque page web, l’information ne doit pas être donnée uniquement par la couleur. Cette règle est-elle respectée ? | H10: =IF(AND(E10="NC",G10=""),"Il manque un message d'erreur", IF(AND(E10<>"NC",G10<>""),"Il faut seulement écrire un message d'erreur pour NC","")) | I10: =E10 -> 0 | J10: ='P02'!E10 -> 0 | K10: ='P03'!K10 -> 0
A11: 10 | B11: 3.2 | C11: Dans chaque page web, le contraste entre la couleur du texte et la couleur de son arrière-plan est-il suffisamment élevé (hors cas particuliers) ? | H11: =IF(AND(E11="NC",G11=""),"Il manque un message d'erreur", IF(AND(E11<>"NC",G11<>""),"Il faut seulement écrire un message d'erreur pour NC","")) | I11: =E11 -> 0 | J11: ='P02'!E11 -> 0 | K11: ='P03'!K11 -> 0
A12: 11 | B12: 4.1 | C12: Chaque média temporel pré-enregistré a-t-il, si nécessaire, une transcription textuelle ou une audiodescription (hors cas particuliers) ? | H12: =IF(AND(E12="NC",G12=""),"Il manque un message d'erreur", IF(AND(E12<>"NC",G12<>""),"Il faut seulement écrire un message d'erreur pour NC","")) | I12: =E12 -> 0 | J12: ='P02'!E12 -> 0 | K12: ='P03'!K12 -> 0
A13: 12 | B13: 4.2 | C13: Pour chaque média temporel pré-enregistré ayant une transcription textuelle ou une audiodescription synchronisée, celles-ci sont-elles pertinentes (hors cas particuliers) ? | D13: =IF(OR(E12="NA",E12="NC"),"NA",T13) -> 0 | H13: =IF(AND(E13="NC",G13=""),"Il manque un message d'erreur", IF(AND(E13<>"NC",G13<>""),"Il faut seulement écrire un message d'erreur pour NC","")) | I13: =E13 -> 0 | J13: ='P02'!E13 -> 0 | K13: ='P03'!K13 -> 0
A14: 13 | B14: 4.3 | C14: Chaque média temporel synchronisé pré-enregistré a-t-il, si nécessaire, des sous-titres synchronisés (hors cas particuliers) ? | D14: =IF(OR(E12="NA",E12="NC"),"NA",T14) -> 0 | H14: =IF(AND(E14="NC",G14=""),"Il manque un message d'erreur", IF(AND(E14<>"NC",G14<>""),"Il faut seulement écrire un message d'erreur pour NC","")) | I14: =E14 -> 0 | J14: ='P02'!E14 -> 0 | K14: ='P03'!K14 -> 0
A15: 14 | B15: 4.4 | C15: Pour chaque média temporel synchronisé pré-enregistré ayant des sous-titres synchronisés, ces sous-titres sont-ils pertinents ? | D15: =IF(OR(E12="NA",E12="NC"),"NA",T15) -> 0 | H15: =IF(AND(E15="NC",G15=""),"Il manque un message d'erreur", IF(AND(E15<>"NC",G15<>""),"Il faut seulement écrire un message d'erreur pour NC","")) | I15: =E15 -> 0 | J15: ='P02'!E15 -> 0 | K15: ='P03'!K15 -> 0
A16: 15 | B16: 4.8 | C16: Chaque média non temporel a-t-il, si nécessaire, une alternative (hors cas particuliers) ? | H16: =IF(AND(E16="NC",G16=""),"Il manque un message d'erreur", IF(AND(E16<>"NC",G16<>""),"Il faut seulement écrire un message d'erreur pour NC","")) | I16: =E16 -> 0 | J16: ='P02'!E16 -> 0 | K16: ='P03'!K16 -> 0
A17: 16 | B17: 4.9 | C17: Pour chaque média non temporel ayant une alternative, cette alternative est-elle pertinente ? | D17: =IF(OR(E16="NA",E16="NC"),"NA",T21) -> 0 | H17: =IF(AND(E17="NC",G17=""),"Il manque un message d'erreur", IF(AND(E17<>"NC",G17<>""),"Il faut seulement écrire un message d'erreur pour NC","")) | I17: =E17 -> 0 | J17: ='P02'!E17 -> 0 | K17: ='P03'!K17 -> 0
A18: 17 | B18: 4.10 | C18: Chaque son déclenché automatiquement est-il contrôlable par l’utilisateur ? | H18: =IF(AND(E18="NC",G18=""),"Il manque un message d'erreur", IF(AND(E18<>"NC",G18<>""),"Il faut seulement écrire un message d'erreur pour NC","")) | I18: =E18 -> 0 | J18: ='P02'!E18 -> 0 | K18: ='P03'!K18 -> 0
A19: 18 | B19: 4.11 | C19: La consultation de chaque média temporel est-elle, si nécessaire, contrôlable par le clavier et tout dispositif de pointage ? | D19: =IF(OR(E12="NA",E12="NC"),"NA",T16) -> 0 | H19: =IF(AND(E19="NC",G19=""),"Il manque un message d'erreur", IF(AND(E19<>"NC",G19<>""),"Il faut seulement écrire un message d'erreur pour NC","")) | I19: =E19 -> 0 | J19: ='P02'!E19 -> 0 | K19: ='P03'!K19 -> 0
A20: 19 | B20: 5.6 | C20: Pour chaque tableau de données, chaque en-tête de colonnes et chaque en-tête de lignes sont-ils correctement déclarés ? | H20: =IF(AND(E20="NC",G20=""),"Il manque un message d'erreur", IF(AND(E20<>"NC",G20<>""),"Il faut seulement écrire un message d'erreur pour NC","")) | I20: =E20 -> 0 | J20: ='P02'!E20 -> 0 | K20: ='P03'!K20 -> 0
A21: 20 | B21: 5.7 | C21: Pour chaque tableau de données, la technique appropriée permettant d’associer chaque cellule avec ses en-têtes est-elle utilisée (hors cas particuliers) ? | D21: =IF(OR(E20="NA",E20="NC"),"NA",T26) -> 0 | H21: =IF(AND(E21="NC",G21=""),"Il manque un message d'erreur", IF(AND(E21<>"NC",G21<>""),"Il faut seulement écrire un message d'erreur pour NC","")) | I21: =E21 -> 0 | J21: ='P02'!E21 -> 0 | K21: ='P03'!K21 -> 0
A22: 21 | B22: 6.1 | C22: Chaque lien est-il explicite (hors cas particuliers) ? | H22: =IF(AND(E22="NC",G22=""),"Il manque un message d'erreur", IF(AND(E22<>"NC",G22<>""),"Il faut seulement écrire un message d'erreur pour NC","")) | I22: =E22 -> 0 | J22: ='P02'!E22 -> 0 | K22: ='P03'!K22 -> 0
A23: 22 | B23: 6.2 | C23: Dans chaque page web, chaque lien a-t-il un intitulé ? | H23: =IF(AND(E23="NC",G23=""),"Il manque un message d'erreur", IF(AND(E23<>"NC",G23<>""),"Il faut seulement écrire un message d'erreur pour NC","")) | I23: =E23 -> 0 | J23: ='P02'!E23 -> 0 | K23: ='P03'!K23 -> 0
A24: 23 | B24: 7.3 | C24: Chaque script est-il contrôlable par le clavier et par tout dispositif de pointage (hors cas particuliers) ? | H24: =IF(AND(E24="NC",G24=""),"Il manque un message d'erreur", IF(AND(E24<>"NC",G24<>""),"Il faut seulement écrire un message d'erreur pour NC","")) | I24: =E24 -> 0 | J24: ='P02'!E24 -> 0 | K24: ='P03'!K24 -> 0
A25: 24 | B25: 8.1 | C25: Chaque page web est-elle définie par un type de document ? | I25: =E25 -> 0 | J25: ='P02'!E25 -> 0 | K25: ='P03'!K25 -> 0
A26: 25 | B26: 8.2 | C26: Pour chaque page web, le code source généré est-il valide selon le type de document spécifié (hors cas particuliers) ? | H26: =IF(AND(E26="NC",G26=""),"Il manque un message d'erreur", IF(AND(E26<>"NC",G26<>""),"Il faut seulement écrire un message d'erreur pour NC","")) | I26: =E26 -> 0 | J26: ='P02'!E26 -> 0 | K26: ='P03'!K26 -> 0
A27: 26 | B27: 8.3 | C27: Dans chaque page web, la langue par défaut est-elle présente ? | H27: =IF(AND(E27="NC",G27=""),"Il manque un message d'erreur", IF(AND(E27<>"NC",G27<>""),"Il faut seulement écrire un message d'erreur pour NC","")) | I27: =E27 -> 0 | J27: ='P02'!E27 -> 0 | K27: ='P03'!K27 -> 0
A28: 27 | B28: 8.4 | C28: Pour chaque page web ayant une langue par défaut, le code de langue est-il pertinent ? | D28: =IF(E27="NA","NA",U35) -> 0 | H28: =IF(AND(E28="NC",G28=""),"Il manque un message d'erreur", IF(AND(E28<>"NC",G28<>""),"Il faut seulement écrire un message d'erreur pour NC","")) | I28: =E28 -> 0 | J28: ='P02'!E28 -> 0 | K28: ='P03'!K28 -> 0
A29: 28 | B29: 8.5 | C29: Chaque page web a-t-elle un titre de page ? | H29: =IF(AND(E29="NC",G29=""),"Il manque un message d'erreur", IF(AND(E29<>"NC",G29<>""),"Il faut seulement écrire un message d'erreur pour NC","")) | I29: =E29 -> 0 | J29: ='P02'!E29 -> 0 | K29: ='P03'!K29 -> 0
A30: 29 | B30: 8.6 | C30: Pour chaque page web ayant un titre de page, ce titre est-il pertinent ? | H30: =IF(AND(E30="NC",G30=""),"Il manque un message d'erreur", IF(AND(E30<>"NC",G30<>""),"Il faut seulement écrire un message d'erreur pour NC","")) | I30: =E30 -> 0 | J30: ='P02'!E30 -> 0 | K30: ='P03'!K30 -> 0
A31: 30 | B31: 8.7 | C31: Dans chaque page web, chaque changement de langue est-il indiqué dans le code source (hors cas particuliers) ? | H31: =IF(AND(E31="NC",G31=""),"Il manque un message d'erreur", IF(AND(E31<>"NC",G31<>""),"Il faut seulement écrire un message d'erreur pour NC","")) | I31: =E31 -> 0 | J31: ='P02'!E31 -> 0 | K31: ='P03'!K31 -> 0
A32: 31 | B32: 8.8 | C32: Dans chaque page web, le code de langue de chaque changement de langue est-il valide et pertinent ? | D32: =IF(OR(E31="NA",E31="NC"),"NA",T40) -> 0 | H32: =IF(AND(E32="NC",G32=""),"Il manque un message d'erreur", IF(AND(E32<>"NC",G32<>""),"Il faut seulement écrire un message d'erreur pour NC","")) | I32: =E32 -> 0 | J32: ='P02'!E32 -> 0 | K32: ='P03'!K32 -> 0
A33: 32 | B33: 9.1 | C33: Dans chaque page web, l’information est-elle structurée par l’utilisation appropriée de titres ? | H33: =IF(AND(E33="NC",G33=""),"Il manque un message d'erreur", IF(AND(E33<>"NC",G33<>""),"Il faut seulement écrire un message d'erreur pour NC","")) | I33: =E33 -> 0 | J33: ='P02'!E33 -> 0 | K33: ='P03'!K33 -> 0
A34: 33 | B34: 9.2 | C34: Dans chaque page web, la structure du document est-elle cohérente (hors cas particuliers) ? | H34: =IF(AND(E34="NC",G34=""),"Il manque un message d'erreur", IF(AND(E34<>"NC",G34<>""),"Il faut seulement écrire un message d'erreur pour NC","")) | I34: =E34 -> 0 | J34: ='P02'!E34 -> 0 | K34: ='P03'!K34 -> 0
A35: 34 | B35: 10.7 | C35: Dans chaque page web, pour chaque élément recevant le focus, la prise de focus est-elle visible ? | H35: =IF(AND(E35="NC",G35=""),"Il manque un message d'erreur", IF(AND(E35<>"NC",G35<>""),"Il faut seulement écrire un message d'erreur pour NC","")) | I35: =E35 -> 0 | J35: ='P02'!E35 -> 0 | K35: ='P03'!K35 -> 0
A36: 35 | B36: 10.8 | C36: Pour chaque page web, les contenus cachés ont-ils vocation à être ignorés par les technologies d’assistance ? | H36: =IF(AND(E36="NC",G36=""),"Il manque un message d'erreur", IF(AND(E36<>"NC",G36<>""),"Il faut seulement écrire un message d'erreur pour NC","")) | I36: =E36 -> 0 | J36: ='P02'!E36 -> 0 | K36: ='P03'!K36 -> 0
A37: 36 | B37: 10.9 | C37: Dans chaque page web, l’information ne doit pas être donnée uniquement par la forme, taille ou position. Cette règle est-elle respectée ? | H37: =IF(AND(E37="NC",G37=""),"Il manque un message d'erreur", IF(AND(E37<>"NC",G37<>""),"Il faut seulement écrire un message d'erreur pour NC","")) | I37: =E37 -> 0 | J37: ='P02'!E37 -> 0 | K37: ='P03'!K37 -> 0
A38: 37 | B38: 10.10 | C38: Dans chaque page web, l’information ne doit pas être donnée par la forme, taille ou position uniquement. Cette règle est-elle implémentée de façon pertinente ? | H38: =IF(AND(E38="NC",G38=""),"Il manque un message d'erreur", IF(AND(E38<>"NC",G38<>""),"Il faut seulement écrire un message d'erreur pour NC","")) | I38: =E38 -> 0 | J38: ='P02'!E38 -> 0 | K38: ='P03'!K38 -> 0
A39: 38 | B39: 10.14 | C39: Dans chaque page web, les contenus additionnels apparaissant via les styles CSS uniquement peuvent-ils être rendus visibles au clavier et par tout dispositif de pointage ? | H39: =IF(AND(E39="NC",G39=""),"Il manque un message d'erreur", IF(AND(E39<>"NC",G39<>""),"Il faut seulement écrire un message d'erreur pour NC","")) | I39: =E39 -> 0 | J39: ='P02'!E39 -> 0 | K39: ='P03'!K39 -> 0
A40: 39 | B40: 11.1 | C40: Chaque champ de formulaire a-t-il une étiquette ? | H40: =IF(AND(E40="NC",G40=""),"Il manque un message d'erreur", IF(AND(E40<>"NC",G40<>""),"Il faut seulement écrire un message d'erreur pour NC","")) | I40: =E40 -> 0 | J40: ='P02'!E40 -> 0 | K40: ='P03'!K40 -> 0
...

Sheet P02
A1: Critère-INC | B1: Critère | C1: Recommandation | D1: Statut-Auto-NA | E1: Statut | F1: Dérogation | G1: Problèmes détectés | H1: Check-Problèmes-Détectés | I1: P01 | J1: ="P02 " & COUNTA(E2:E54) &"/"&COUNTA(C2:C54) -> P02 0/53 | K1: P03
A2: 1 | B2: 1.1 | C2: Chaque image porteuse d’information a-t-elle une alternative textuelle ? | H2: =IF(AND(E2="NC",G2=""),"Il manque un message d'erreur", IF(AND(E2<>"NC",G2<>""),"Il faut seulement écrire un message d'erreur pour NC","")) | I2: ='P01'!E2 -> 0 | J2: =E2 -> 0 | K2: ='P03'!E2 -> 0
A3: 2 | B3: 1.2 | C3: Chaque image de décoration est-elle correctement ignorée par les technologies d’assistance ? | H3: =IF(AND(E3="NC",G3=""),"Il manque un message d'erreur", IF(AND(E3<>"NC",G3<>""),"Il faut seulement écrire un message d'erreur pour NC","")) | I3: ='P01'!E3 -> 0 | J3: =E3 -> 0 | K3: ='P03'!E3 -> 0
A4: 3 | B4: 1.3 | C4: Pour chaque image porteuse d'information ayant une alternative textuelle, cette alternative est-elle pertinente (hors cas particuliers) ? | D4: =IF(OR(E2="NA",E2="NC"),"NA",T3) -> 0 | H4: =IF(AND(E4="NC",G4=""),"Il manque un message d'erreur", IF(AND(E4<>"NC",G4<>""),"Il faut seulement écrire un message d'erreur pour NC","")) | I4: ='P01'!E4 -> 0 | J4: =E4 -> 0 | K4: ='P03'!E4 -> 0
A5: 4 | B5: 1.4 | C5: Pour chaque image utilisée comme CAPTCHA ou comme image-test, ayant une alternative textuelle, cette alternative permet-elle d’identifier la nature et la fonction de l’image ? | H5: =IF(AND(E5="NC",G5=""),"Il manque un message d'erreur", IF(AND(E5<>"NC",G5<>""),"Il faut seulement écrire un message d'erreur pour NC","")) | I5: ='P01'!E5 -> 0 | J5: =E5 -> 0 | K5: ='P03'!E5 -> 0
A6: 5 | B6: 1.5 | C6: Pour chaque image utilisée comme CAPTCHA, une solution d’accès alternatif au contenu ou à la fonction du CAPTCHA est-elle présente ? | H6: =IF(AND(E6="NC",G6=""),"Il manque un message d'erreur", IF(AND(E6<>"NC",G6<>""),"Il faut seulement écrire un message d'erreur pour NC","")) | I6: ='P01'!E6 -> 0 | J6: =E6 -> 0 | K6: ='P03'!E6 -> 0
A7: 6 | B7: 1.6 | C7: Chaque image porteuse d’information a-t-elle, si nécessaire, une description détaillée ? | D7: =IF(OR(E2="NA",E2="NC"),"NA",T6) -> 0 | H7: =IF(AND(E7="NC",G7=""),"Il manque un message d'erreur", IF(AND(E7<>"NC",G7<>""),"Il faut seulement écrire un message d'erreur pour NC","")) | I7: ='P01'!E7 -> 0 | J7: =E7 -> 0 | K7: ='P03'!E7 -> 0
A8: 7 | B8: 1.7 | C8: Pour chaque image porteuse d’information ayant une description détaillée, cette description est-elle pertinente ? | D8: =IF(OR(E2="NA",E2="NC"),"NA",T7) -> 0 | H8: =IF(AND(E8="NC",G8=""),"Il manque un message d'erreur", IF(AND(E8<>"NC",G8<>""),"Il faut seulement écrire un message d'erreur pour NC","")) | I8: ='P01'!E8 -> 0 | J8: =E8 -> 0 | K8: ='P03'!E8 -> 0
A9: 8 | B9: 2.1 | C9: Chaque cadre a-t-il un titre de cadre ? | H9: =IF(AND(E9="NC",G9=""),"Il manque un message d'erreur", IF(AND(E9<>"NC",G9<>""),"Il faut seulement écrire un message d'erreur pour NC","")) | I9: ='P01'!E9 -> 0 | J9: =E9 -> 0 | K9: ='P03'!E9 -> 0
A10: 9 | B10: 3.1 | C10: Dans chaque page web, l’information ne doit pas être donnée uniquement par la couleur. Cette règle est-elle respectée ? | H10: =IF(AND(E10="NC",G10=""),"Il manque un message d'erreur", IF(AND(E10<>"NC",G10<>""),"Il faut seulement écrire un message d'erreur pour NC","")) | I10: ='P01'!E10 -> 0 | J10: =E10 -> 0 | K10: ='P03'!E10 -> 0
A11: 10 | B11: 3.2 | C11: Dans chaque page web, le contraste entre la couleur du texte et la couleur de son arrière-plan est-il suffisamment élevé (hors cas particuliers) ? | H11: =IF(AND(E11="NC",G11=""),"Il manque un message d'erreur", IF(AND(E11<>"NC",G11<>""),"Il faut seulement écrire un message d'erreur pour NC","")) | I11: ='P01'!E11 -> 0 | J11: =E11 -> 0 | K11: ='P03'!E11 -> 0
A12: 11 | B12: 4.1 | C12: Chaque média temporel pré-enregistré a-t-il, si nécessaire, une transcription textuelle ou une audiodescription (hors cas particuliers) ? | H12: =IF(AND(E12="NC",G12=""),"Il manque un message d'erreur", IF(AND(E12<>"NC",G12<>""),"Il faut seulement écrire un message d'erreur pour NC","")) | I12: ='P01'!E12 -> 0 | J12: =E12 -> 0 | K12: ='P03'!E12 -> 0
A13: 12 | B13: 4.2 | C13: Pour chaque média temporel pré-enregistré ayant une transcription textuelle ou une audiodescription synchronisée, celles-ci sont-elles pertinentes (hors cas particuliers) ? | D13: =IF(OR(E12="NA",E12="NC"),"NA",T13) -> 0 | H13: =IF(AND(E13="NC",G13=""),"Il manque un message d'erreur", IF(AND(E13<>"NC",G13<>""),"Il faut seulement écrire un message d'erreur pour NC","")) | I13: ='P01'!E13 -> 0 | J13: =E13 -> 0 | K13: ='P03'!E13 -> 0
A14: 13 | B14: 4.3 | C14: Chaque média temporel synchronisé pré-enregistré a-t-il, si nécessaire, des sous-titres synchronisés (hors cas particuliers) ? | D14: =IF(OR(E12="NA",E12="NC"),"NA",T14) -> 0 | H14: =IF(AND(E14="NC",G14=""),"Il manque un message d'erreur", IF(AND(E14<>"NC",G14<>""),"Il faut seulement écrire un message d'erreur pour NC","")) | I14: ='P01'!E14 -> 0 | J14: =E14 -> 0 | K14: ='P03'!E14 -> 0
A15: 14 | B15: 4.4 | C15: Pour chaque média temporel synchronisé pré-enregistré ayant des sous-titres synchronisés, ces sous-titres sont-ils pertinents ? | D15: =IF(OR(E12="NA",E12="NC"),"NA",T15) -> 0 | H15: =IF(AND(E15="NC",G15=""),"Il manque un message d'erreur", IF(AND(E15<>"NC",G15<>""),"Il faut seulement écrire un message d'erreur pour NC","")) | I15: ='P01'!E15 -> 0 | J15: =E15 -> 0 | K15: ='P03'!E15 -> 0
A16: 15 | B16: 4.8 | C16: Chaque média non temporel a-t-il, si nécessaire, une alternative (hors cas particuliers) ? | H16: =IF(AND(E16="NC",G16=""),"Il manque un message d'erreur", IF(AND(E16<>"NC",G16<>""),"Il faut seulement écrire un message d'erreur pour NC","")) | I16: ='P01'!E16 -> 0 | J16: =E16 -> 0 | K16: ='P03'!E16 -> 0
A17: 16 | B17: 4.9 | C17: Pour chaque média non temporel ayant une alternative, cette alternative est-elle pertinente ? | D17: =IF(OR(E16="NA",E16="NC"),"NA",T21) -> 0 | H17: =IF(AND(E17="NC",G17=""),"Il manque un message d'erreur", IF(AND(E17<>"NC",G17<>""),"Il faut seulement écrire un message d'erreur pour NC","")) | I17: ='P01'!E17 -> 0 | J17: =E17 -> 0 | K17: ='P03'!E17 -> 0
A18: 17 | B18: 4.10 | C18: Chaque son déclenché automatiquement est-il contrôlable par l’utilisateur ? | H18: =IF(AND(E18="NC",G18=""),"Il manque un message d'erreur", IF(AND(E18<>"NC",G18<>""),"Il faut seulement écrire un message d'erreur pour NC","")) | I18: ='P01'!E18 -> 0 | J18: =E18 -> 0 | K18: ='P03'!E18 -> 0
A19: 18 | B19: 4.11 | C19: La consultation de chaque média temporel est-elle, si nécessaire, contrôlable par le clavier et tout dispositif de pointage ? | D19: =IF(OR(E12="NA",E12="NC"),"NA",T16) -> 0 | H19: =IF(AND(E19="NC",G19=""),"Il manque un message d'erreur", IF(AND(E19<>"NC",G19<>""),"Il faut seulement écrire un message d'erreur pour NC","")) | I19: ='P01'!E19 -> 0 | J19: =E19 -> 0 | K19: ='P03'!E19 -> 0
A20: 19 | B20: 5.6 | C20: Pour chaque tableau de données, chaque en-tête de colonnes et chaque en-tête de lignes sont-ils correctement déclarés ? | H20: =IF(AND(E20="NC",G20=""),"Il manque un message d'erreur", IF(AND(E20<>"NC",G20<>""),"Il faut seulement écrire un message d'erreur pour NC","")) | I20: ='P01'!E20 -> 0 | J20: =E20 -> 0 | K20: ='P03'!E20 -> 0
A21: 20 | B21: 5.7 | C21: Pour chaque tableau de données, la technique appropriée permettant d’associer chaque cellule avec ses en-têtes est-elle utilisée (hors cas particuliers) ? | D21: =IF(OR(E20="NA",E20="NC"),"NA",T27) -> 0 | H21: =IF(AND(E21="NC",G21=""),"Il manque un message d'erreur", IF(AND(E21<>"NC",G21<>""),"Il faut seulement écrire un message d'erreur pour NC","")) | I21: ='P01'!E21 -> 0 | J21: =E21 -> 0 | K21: ='P03'!E21 -> 0
A22: 21 | B22: 6.1 | C22: Chaque lien est-il explicite (hors cas particuliers) ? | H22: =IF(AND(E22="NC",G22=""),"Il manque un message d'erreur", IF(AND(E22<>"NC",G22<>""),"Il faut seulement écrire un message d'erreur pour NC","")) | I22: ='P01'!E22 -> 0 | J22: =E22 -> 0 | K22: ='P03'!E22 -> 0
A23: 22 | B23: 6.2 | C23: Dans chaque page web, chaque lien a-t-il un intitulé ? | H23: =IF(AND(E23="NC",G23=""),"Il manque un message d'erreur", IF(AND(E23<>"NC",G23<>""),"Il faut seulement écrire un message d'erreur pour NC","")) | I23: ='P01'!E23 -> 0 | J23: =E23 -> 0 | K23: ='P03'!E23 -> 0
A24: 23 | B24: 7.3 | C24: Chaque script est-il contrôlable par le clavier et par tout dispositif de pointage (hors cas particuliers) ? | H24: =IF(AND(E24="NC",G24=""),"Il manque un message d'erreur", IF(AND(E24<>"NC",G24<>""),"Il faut seulement écrire un message d'erreur pour NC","")) | I24: ='P01'!E24 -> 0 | J24: =E24 -> 0 | K24: ='P03'!E24 -> 0
A25: 24 | B25: 8.1 | C25: Chaque page web est-elle définie par un type de document ? | I25: ='P01'!E25 -> 0 | J25: =E25 -> 0 | K25: ='P03'!E25 -> 0
A26: 25 | B26: 8.2 | C26: Pour chaque page web, le code source généré est-il valide selon le type de document spécifié (hors cas particuliers) ? | H26: =IF(AND(E26="NC",G26=""),"Il manque un message d'erreur", IF(AND(E26<>"NC",G26<>""),"Il faut seulement écrire un message d'erreur pour NC","")) | I26: ='P01'!E26 -> 0 | J26: =E26 -> 0 | K26: ='P03'!E26 -> 0
A27: 26 | B27: 8.3 | C27: Dans chaque page web, la langue par défaut est-elle présente ? | H27: =IF(AND(E27="NC",G27=""),"Il manque un message d'erreur", IF(AND(E27<>"NC",G27<>""),"Il faut seulement écrire un message d'erreur pour NC","")) | I27: ='P01'!E27 -> 0 | J27: =E27 -> 0 | K27: ='P03'!E27 -> 0
A28: 27 | B28: 8.4 | C28: Pour chaque page web ayant une langue par défaut, le code de langue est-il pertinent ? | H28: =IF(AND(E28="NC",G28=""),"Il manque un message d'erreur", IF(AND(E28<>"NC",G28<>""),"Il faut seulement écrire un message d'erreur pour NC","")) | I28: ='P01'!E28 -> 0 | J28: =E28 -> 0 | K28: ='P03'!E28 -> 0
A29: 28 | B29: 8.5 | C29: Chaque page web a-t-elle un titre de page ? | D29: =IF(E28="NA","NA",U36) -> 0 | H29: =IF(AND(E29="NC",G29=""),"Il manque un message d'erreur", IF(AND(E29<>"NC",G29<>""),"Il faut seulement écrire un message d'erreur pour NC","")) | I29: ='P01'!E29 -> 0 | J29: =E29 -> 0 | K29: ='P03'!E29 -> 0
A30: 29 | B30: 8.6 | C30: Pour chaque page web ayant un titre de page, ce titre est-il pertinent ? | H30: =IF(AND(E30="NC",G30=""),"Il manque un message d'erreur", IF(AND(E30<>"NC",G30<>""),"Il faut seulement écrire un message d'erreur pour NC","")) | I30: ='P01'!E30 -> 0 | J30: =E30 -> 0 | K30: ='P03'!E30 -> 0
A31: 30 | B31: 8.7 | C31: Dans chaque page web, chaque changement de langue est-il indiqué dans le code source (hors cas particuliers) ? | H31: =IF(AND(E31="NC",G31=""),"Il manque un message d'erreur", IF(AND(E31<>"NC",G31<>""),"Il faut seulement écrire un message d'erreur pour NC","")) | I31: ='P01'!E31 -> 0 | J31: =E31 -> 0 | K31: ='P03'!E31 -> 0
A32: 31 | B32: 8.8 | C32: Dans chaque page web, le code de langue de chaque changement de langue est-il valide et pertinent ? | H32: =IF(AND(E32="NC",G32=""),"Il manque un message d'erreur", IF(AND(E32<>"NC",G32<>""),"Il faut seulement écrire un message d'erreur pour NC","")) | I32: ='P01'!E32 -> 0 | J32: =E32 -> 0 | K32: ='P03'!E32 -> 0
A33: 32 | B33: 9.1 | C33: Dans chaque page web, l’information est-elle structurée par l’utilisation appropriée de titres ? | D33: =IF(OR(E32="NA",E32="NC"),"NA",T41) -> 0 | H33: =IF(AND(E33="NC",G33=""),"Il manque un message d'erreur", IF(AND(E33<>"NC",G33<>""),"Il faut seulement écrire un message d'erreur pour NC","")) | I33: ='P01'!E33 -> 0 | J33: =E33 -> 0 | K33: ='P03'!E33 -> 0
A34: 33 | B34: 9.2 | C34: Dans chaque page web, la structure du document est-elle cohérente (hors cas particuliers) ? | H34: =IF(AND(E34="NC",G34=""),"Il manque un message d'erreur", IF(AND(E34<>"NC",G34<>""),"Il faut seulement écrire un message d'erreur pour NC","")) | I34: ='P01'!E34 -> 0 | J34: =E34 -> 0 | K34: ='P03'!E34 -> 0
A35: 34 | B35: 10.7 | C35: Dans chaque page web, pour chaque élément recevant le focus, la prise de focus est-elle visible ? | H35: =IF(AND(E35="NC",G35=""),"Il manque un message d'erreur", IF(AND(E35<>"NC",G35<>""),"Il faut seulement écrire un message d'erreur pour NC","")) | I35: ='P01'!E35 -> 0 | J35: =E35 -> 0 | K35: ='P03'!E35 -> 0
A36: 35 | B36: 10.8 | C36: Pour chaque page web, les contenus cachés ont-ils vocation à être ignorés par les technologies d’assistance ? | H36: =IF(AND(E36="NC",G36=""),"Il manque un message d'erreur", IF(AND(E36<>"NC",G36<>""),"Il faut seulement écrire un message d'erreur pour NC","")) | I36: ='P01'!E36 -> 0 | J36: =E36 -> 0 | K36: ='P03'!E36 -> 0
A37: 36 | B37: 10.9 | C37: Dans chaque page web, l’information ne doit pas être donnée uniquement par la forme, taille ou position. Cette règle est-elle respectée ? | H37: =IF(AND(E37="NC",G37=""),"Il manque un message d'erreur", IF(AND(E37<>"NC",G37<>""),"Il faut seulement écrire un message d'erreur pour NC","")) | I37: ='P01'!E37 -> 0 | J37: =E37 -> 0 | K37: ='P03'!E37 -> 0
A38: 37 | B38: 10.10 | C38: Dans chaque page web, l’information ne doit pas être donnée par la forme, taille ou position uniquement. Cette règle est-elle implémentée de façon pertinente ? | H38: =IF(AND(E38="NC",G38=""),"Il manque un message d'erreur", IF(AND(E38<>"NC",G38<>""),"Il faut seulement écrire un message d'erreur pour NC","")) | I38: ='P01'!E38 -> 0 | J38: =E38 -> 0 | K38: ='P03'!E38 -> 0
A39: 38 | B39: 10.14 | C39: Dans chaque page web, les contenus additionnels apparaissant via les styles CSS uniquement peuvent-ils être rendus visibles au clavier et par tout dispositif de pointage ? | H39: =IF(AND(E39="NC",G39=""),"Il manque un message d'erreur", IF(AND(E39<>"NC",G39<>""),"Il faut seulement écrire un message d'erreur pour NC","")) | I39: ='P01'!E39 -> 0 | J39: =E39 -> 0 | K39: ='P03'!E39 -> 0
A40: 39 | B40: 11.1 | C40: Chaque champ de formulaire a-t-il une étiquette ? | H40: =IF(AND(E40="NC",G40=""),"Il manque un message d'erreur", IF(AND(E40<>"NC",G40<>""),"Il faut seulement écrire un message d'erreur pour NC","")) | I40: ='P01'!E40 -> 0 | J40: =E40 -> 0 | K40: ='P03'!E40 -> 0
...

Sheet P03
A1: Critère-INC | B1: Critère | C1: Recommandation | D1: Statut-Auto-NA | E1: Statut | F1: Dérogation | G1: Problèmes détectés | H1: Check-Problèmes-Détectés | I1: P01 | J1: P02 | K1: ="P03 " & COUNTA(E2:E54) &"/"&COUNTA(C2:C54) -> P03 0/53
A2: 1 | B2: 1.1 | C2: Chaque image porteuse d’information a-t-elle une alternative textuelle ? | H2: =IF(AND(E2="NC",G2=""),"Il manque un message d'erreur", IF(AND(E2<>"NC",G2<>""),"Il faut seulement écrire un message d'erreur pour NC","")) | I2: ='P01'!E2 -> 0 | J2: ='P02'!E2 -> 0 | K2: =E2 -> 0
A3: 2 | B3: 1.2 | C3: Chaque image de décoration est-elle correctement ignorée par les technologies d’assistance ? | H3: =IF(AND(E3="NC",G3=""),"Il manque un message d'erreur", IF(AND(E3<>"NC",G3<>""),"Il faut seulement écrire un message d'erreur pour NC","")) | I3: ='P01'!E3 -> 0 | J3: ='P02'!E3 -> 0 | K3: =E3 -> 0
A4: 3 | B4: 1.3 | C4: Pour chaque image porteuse d'information ayant une alternative textuelle, cette alternative est-elle pertinente (hors cas particuliers) ? | D4: =IF(OR(E2="NA",E2="NC"),"NA",T3) -> 0 | H4: =IF(AND(E4="NC",G4=""),"Il manque un message d'erreur", IF(AND(E4<>"NC",G4<>""),"Il faut seulement écrire un message d'erreur pour NC","")) | I4: ='P01'!E4 -> 0 | J4: ='P02'!E4 -> 0 | K4: =E4 -> 0
A5: 4 | B5: 1.4 | C5: Pour chaque image utilisée comme CAPTCHA ou comme image-test, ayant une alternative textuelle, cette alternative permet-elle d’identifier la nature et la fonction de l’image ? | H5: =IF(AND(E5="NC",G5=""),"Il manque un message d'erreur", IF(AND(E5<>"NC",G5<>""),"Il faut seulement écrire un message d'erreur pour NC","")) | I5: ='P01'!E5 -> 0 | J5: ='P02'!E5 -> 0 | K5: =E5 -> 0
A6: 5 | B6: 1.5 | C6: Pour chaque image utilisée comme CAPTCHA, une solution d’accès alternatif au contenu ou à la fonction du CAPTCHA est-elle présente ? | H6: =IF(AND(E6="NC",G6=""),"Il manque un message d'erreur", IF(AND(E6<>"NC",G6<>""),"Il faut seulement écrire un message d'erreur pour NC","")) | I6: ='P01'!E6 -> 0 | J6: ='P02'!E6 -> 0 | K6: =E6 -> 0
A7: 6 | B7: 1.6 | C7: Chaque image porteuse d’information a-t-elle, si nécessaire, une description détaillée ? | D7: =IF(OR(E2="NA",E2="NC"),"NA",T6) -> 0 | H7: =IF(AND(E7="NC",G7=""),"Il manque un message d'erreur", IF(AND(E7<>"NC",G7<>""),"Il faut seulement écrire un message d'erreur pour NC","")) | I7: ='P01'!E7 -> 0 | J7: ='P02'!E7 -> 0 | K7: =E7 -> 0
A8: 7 | B8: 1.7 | C8: Pour chaque image porteuse d’information ayant une description détaillée, cette description est-elle pertinente ? | D8: =IF(OR(E2="NA",E2="NC"),"NA",T7) -> 0 | H8: =IF(AND(E8="NC",G8=""),"Il manque un message d'erreur", IF(AND(E8<>"NC",G8<>""),"Il faut seulement écrire un message d'erreur pour NC","")) | I8: ='P01'!E8 -> 0 | J8: ='P02'!E8 -> 0 | K8: =E8 -> 0
A9: 8 | B9: 2.1 | C9: Chaque cadre a-t-il un titre de cadre ? | H9: =IF(AND(E9="NC",G9=""),"Il manque un message d'erreur", IF(AND(E9<>"NC",G9<>""),"Il faut seulement écrire un message d'erreur pour NC","")) | I9: ='P01'!E9 -> 0 | J9: ='P02'!E9 -> 0 | K9: =E9 -> 0
A10: 9 | B10: 3.1 | C10: Dans chaque page web, l’information ne doit pas être donnée uniquement par la couleur. Cette règle est-elle respectée ? | H10: =IF(AND(E10="NC",G10=""),"Il manque un message d'erreur", IF(AND(E10<>"NC",G10<>""),"Il faut seulement écrire un message d'erreur pour NC","")) | I10: ='P01'!E10 -> 0 | J10: ='P02'!E10 -> 0 | K10: =E10 -> 0
A11: 10 | B11: 3.2 | C11: Dans chaque page web, le contraste entre la couleur du texte et la couleur de son arrière-plan est-il suffisamment élevé (hors cas particuliers) ? | H11: =IF(AND(E11="NC",G11=""),"Il manque un message d'erreur", IF(AND(E11<>"NC",G11<>""),"Il faut seulement écrire un message d'erreur pour NC","")) | I11: ='P01'!E11 -> 0 | J11: ='P02'!E11 -> 0 | K11: =E11 -> 0
A12: 11 | B12: 4.1 | C12: Chaque média temporel pré-enregistré a-t-il, si nécessaire, une transcription textuelle ou une audiodescription (hors cas particuliers) ? | H12: =IF(AND(E12="NC",G12=""),"Il manque un message d'erreur", IF(AND(E12<>"NC",G12<>""),"Il faut seulement écrire un message d'erreur pour NC","")) | I12: ='P01'!E12 -> 0 | J12: ='P02'!E12 -> 0 | K12: =E12 -> 0
A13: 12 | B13: 4.2 | C13: Pour chaque média temporel pré-enregistré ayant une transcription textuelle ou une audiodescription synchronisée, celles-ci sont-elles pertinentes (hors cas particuliers) ? | D13: =IF(OR(E12="NA",E12="NC"),"NA",T13) -> 0 | H13: =IF(AND(E13="NC",G13=""),"Il manque un message d'erreur", IF(AND(E13<>"NC",G13<>""),"Il faut seulement écrire un message d'erreur pour NC","")) | I13: ='P01'!E13 -> 0 | J13: ='P02'!E13 -> 0 | K13: =E13 -> 0
A14: 13 | B14: 4.3 | C14: Chaque média temporel synchronisé pré-enregistré a-t-il, si nécessaire, des sous-titres synchronisés (hors cas particuliers) ? | D14: =IF(OR(E12="NA",E12="NC"),"NA",T14) -> 0 | H14: =IF(AND(E14="NC",G14=""),"Il manque un message d'erreur", IF(AND(E14<>"NC",G14<>""),"Il faut seulement écrire un message d'erreur pour NC","")) | I14: ='P01'!E14 -> 0 | J14: ='P02'!E14 -> 0 | K14: =E14 -> 0
A15: 14 | B15: 4.4 | C15: Pour chaque média temporel synchronisé pré-enregistré ayant des sous-titres synchronisés, ces sous-titres sont-ils pertinents ? | D15: =IF(OR(E12="NA",E12="NC"),"NA",T15) -> 0 | H15: =IF(AND(E15="NC",G15=""),"Il manque un message d'erreur", IF(AND(E15<>"NC",G15<>""),"Il faut seulement écrire un message d'erreur pour NC","")) | I15: ='P01'!E15 -> 0 | J15: ='P02'!E15 -> 0 | K15: =E15 -> 0
A16: 15 | B16: 4.8 | C16: Chaque média non temporel a-t-il, si nécessaire, une alternative (hors cas particuliers) ? | H16: =IF(AND(E16="NC",G16=""),"Il manque un message d'erreur", IF(AND(E16<>"NC",G16<>""),"Il faut seulement écrire un message d'erreur pour NC","")) | I16: ='P01'!E16 -> 0 | J16: ='P02'!E16 -> 0 | K16: =E16 -> 0
A17: 16 | B17: 4.9 | C17: Pour chaque média non temporel ayant une alternative, cette alternative est-elle pertinente ? | D17: =IF(OR(E16="NA",E16="NC"),"NA",T21) -> 0 | H17: =IF(AND(E17="NC",G17=""),"Il manque un message d'erreur", IF(AND(E17<>"NC",G17<>""),"Il faut seulement écrire un message d'erreur pour NC","")) | I17: ='P01'!E17 -> 0 | J17: ='P02'!E17 -> 0 | K17: =E17 -> 0
A18: 17 | B18: 4.10 | C18: Chaque son déclenché automatiquement est-il contrôlable par l’utilisateur ? | H18: =IF(AND(E18="NC",G18=""),"Il manque un message d'erreur", IF(AND(E18<>"NC",G18<>""),"Il faut seulement écrire un message d'erreur pour NC","")) | I18: ='P01'!E18 -> 0 | J18: ='P02'!E18 -> 0 | K18: =E18 -> 0
A19: 18 | B19: 4.11 | C19: La consultation de chaque média temporel est-elle, si nécessaire, contrôlable par le clavier et tout dispositif de pointage ? | D19: =IF(OR(E12="NA",E12="NC"),"NA",T16) -> 0 | H19: =IF(AND(E19="NC",G19=""),"Il manque un message d'erreur", IF(AND(E19<>"NC",G19<>""),"Il faut seulement écrire un message d'erreur pour NC","")) | I19: ='P01'!E19 -> 0 | J19: ='P02'!E19 -> 0 | K19: =E19 -> 0
A20: 19 | B20: 5.6 | C20: Pour chaque tableau de données, chaque en-tête de colonnes et chaque en-tête de lignes sont-ils correctement déclarés ? | H20: =IF(AND(E20="NC",G20=""),"Il manque un message d'erreur", IF(AND(E20<>"NC",G20<>""),"Il faut seulement écrire un message d'erreur pour NC","")) | I20: ='P01'!E20 -> 0 | J20: ='P02'!E20 -> 0 | K20: =E20 -> 0
A21: 20 | B21: 5.7 | C21: Pour chaque tableau de données, la technique appropriée permettant d’associer chaque cellule avec ses en-têtes est-elle utilisée (hors cas particuliers) ? | D21: =IF(OR(E20="NA",E20="NC"),"NA",T27) -> 0 | H21: =IF(AND(E21="NC",G21=""),"Il manque un message d'erreur", IF(AND(E21<>"NC",G21<>""),"Il faut seulement écrire un message d'erreur pour NC","")) | I21: ='P01'!E21 -> 0 | J21: ='P02'!E21 -> 0 | K21: =E21 -> 0
A22: 21 | B22: 6.1 | C22: Chaque lien est-il explicite (hors cas particuliers) ? | H22: =IF(AND(E22="NC",G22=""),"Il manque un message d'erreur", IF(AND(E22<>"NC",G22<>""),"Il faut seulement écrire un message d'erreur pour NC","")) | I22: ='P01'!E22 -> 0 | J22: ='P02'!E22 -> 0 | K22: =E22 -> 0
A23: 22 | B23: 6.2 | C23: Dans chaque page web, chaque lien a-t-il un intitulé ? | H23: =IF(AND(E23="NC",G23=""),"Il manque un message d'erreur", IF(AND(E23<>"NC",G23<>""),"Il faut seulement écrire un message d'erreur pour NC","")) | I23: ='P01'!E23 -> 0 | J23: ='P02'!E23 -> 0 | K23: =E23 -> 0
A24: 23 | B24: 7.3 | C24: Chaque script est-il contrôlable par le clavier et par tout dispositif de pointage (hors cas particuliers) ? | H24: =IF(AND(E24="NC",G24=""),"Il manque un message d'erreur", IF(AND(E24<>"NC",G24<>""),"Il faut seulement écrire un message d'erreur pour NC","")) | I24: ='P01'!E24 -> 0 | J24: ='P02'!E24 -> 0 | K24: =E24 -> 0
A25: 24 | B25: 8.1 | C25: Chaque page web est-elle définie par un type de document ? | I25: ='P01'!E25 -> 0 | J25: ='P02'!E25 -> 0 | K25: =E25 -> 0
A26: 25 | B26: 8.2 | C26: Pour chaque page web, le code source généré est-il valide selon le type de document spécifié (hors cas particuliers) ? | H26: =IF(AND(E26="NC",G26=""),"Il manque un message d'erreur", IF(AND(E26<>"NC",G26<>""),"Il faut seulement écrire un message d'erreur pour NC","")) | I26: ='P01'!E26 -> 0 | J26: ='P02'!E26 -> 0 | K26: =E26 -> 0
A27: 26 | B27: 8.3 | C27: Dans chaque page web, la langue par défaut est-elle présente ? | H27: =IF(AND(E27="NC",G27=""),"Il manque un message d'erreur", IF(AND(E27<>"NC",G27<>""),"Il faut seulement écrire un message d'erreur pour NC","")) | I27: ='P01'!E27 -> 0 | J27: ='P02'!E27 -> 0 | K27: =E27 -> 0
A28: 27 | B28: 8.4 | C28: Pour chaque page web ayant une langue par défaut, le code de langue est-il pertinent ? | H28: =IF(AND(E28="NC",G28=""),"Il manque un message d'erreur", IF(AND(E28<>"NC",G28<>""),"Il faut seulement écrire un message d'erreur pour NC","")) | I28: ='P01'!E28 -> 0 | J28: ='P02'!E28 -> 0 | K28: =E28 -> 0
A29: 28 | B29: 8.5 | C29: Chaque page web a-t-elle un titre de page ? | D29: =IF(E28="NA","NA",U36) -> 0 | H29: =IF(AND(E29="NC",G29=""),"Il manque un message d'erreur", IF(AND(E29<>"NC",G29<>""),"Il faut seulement écrire un message d'erreur pour NC","")) | I29: ='P01'!E29 -> 0 | J29: ='P02'!E29 -> 0 | K29: =E29 -> 0
A30: 29 | B30: 8.6 | C30: Pour chaque page web ayant un titre de page, ce titre est-il pertinent ? | H30: =IF(AND(E30="NC",G30=""),"Il manque un message d'erreur", IF(AND(E30<>"NC",G30<>""),"Il faut seulement écrire un message d'erreur pour NC","")) | I30: ='P01'!E30 -> 0 | J30: ='P02'!E30 -> 0 | K30: =E30 -> 0
A31: 30 | B31: 8.7 | C31: Dans chaque page web, chaque changement de langue est-il indiqué dans le code source (hors cas particuliers) ? | H31: =IF(AND(E31="NC",G31=""),"Il manque un message d'erreur", IF(AND(E31<>"NC",G31<>""),"Il faut seulement écrire un message d'erreur pour NC","")) | I31: ='P01'!E31 -> 0 | J31: ='P02'!E31 -> 0 | K31: =E31 -> 0
A32: 31 | B32: 8.8 | C32: Dans chaque page web, le code de langue de chaque changement de langue est-il valide et pertinent ? | H32: =IF(AND(E32="NC",G32=""),"Il manque un message d'erreur", IF(AND(E32<>"NC",G32<>""),"Il faut seulement écrire un message d'erreur pour NC","")) | I32: ='P01'!E32 -> 0 | J32: ='P02'!E32 -> 0 | K32: =E32 -> 0
A33: 32 | B33: 9.1 | C33: Dans chaque page web, l’information est-elle structurée par l’utilisation appropriée de titres ? | D33: =IF(OR(E32="NA",E32="NC"),"NA",T41) -> 0 | H33: =IF(AND(E33="NC",G33=""),"Il manque un message d'erreur", IF(AND(E33<>"NC",G33<>""),"Il faut seulement écrire un message d'erreur pour NC","")) | I33: ='P01'!E33 -> 0 | J33: ='P02'!E33 -> 0 | K33: =E33 -> 0
A34: 33 | B34: 9.2 | C34: Dans chaque page web, la structure du document est-elle cohérente (hors cas particuliers) ? | H34: =IF(AND(E34="NC",G34=""),"Il manque un message d'erreur", IF(AND(E34<>"NC",G34<>""),"Il faut seulement écrire un message d'erreur pour NC","")) | I34: ='P01'!E34 -> 0 | J34: ='P02'!E34 -> 0 | K34: =E34 -> 0
